[2023-11-26 11:02:37,925] ERROR log_exception() L1449 Exception on /clientes [GET] - call_trace=C:\Users\Hugo Nunes\AppData\Local\Programs\Python\Python311\Lib\site-packages\flask\app.py L1449
Traceback (most recent call last):
  File "C:\Users\Hugo Nunes\AppData\Local\Programs\Python\Python311\Lib\site-packages\flask\app.py", line 2073, in wsgi_app
    response = self.full_dispatch_request()
               ^^^^^^^^^^^^^^^^^^^^^^^^^^^^
  File "C:\Users\Hugo Nunes\AppData\Local\Programs\Python\Python311\Lib\site-packages\flask\app.py", line 1519, in full_dispatch_request
    rv = self.handle_user_exception(e)
         ^^^^^^^^^^^^^^^^^^^^^^^^^^^^^
  File "C:\Users\Hugo Nunes\AppData\Local\Programs\Python\Python311\Lib\site-packages\flask_cors\extension.py", line 165, in wrapped_function
    return cors_after_request(app.make_response(f(*args, **kwargs)))
                                                ^^^^^^^^^^^^^^^^^^
  File "C:\Users\Hugo Nunes\AppData\Local\Programs\Python\Python311\Lib\site-packages\flask\app.py", line 1517, in full_dispatch_request
    rv = self.dispatch_request()
         ^^^^^^^^^^^^^^^^^^^^^^^
  File "C:\Users\Hugo Nunes\AppData\Local\Programs\Python\Python311\Lib\site-packages\flask\app.py", line 1503, in dispatch_request
    return self.ensure_sync(self.view_functions[rule.endpoint])(**req.view_args)
           ^^^^^^^^^^^^^^^^^^^^^^^^^^^^^^^^^^^^^^^^^^^^^^^^^^^^^^^^^^^^^^^^^^^^^
  File "C:\Users\Hugo Nunes\AppData\Local\Programs\Python\Python311\Lib\site-packages\flask_openapi3\scaffold.py", line 109, in wrapper
    resp = _do_wrapper(
           ^^^^^^^^^^^^
  File "C:\Users\Hugo Nunes\AppData\Local\Programs\Python\Python311\Lib\site-packages\flask_openapi3\do_wrapper.py", line 135, in _do_wrapper
    response = func(**request_kwargs)
               ^^^^^^^^^^^^^^^^^^^^^^
  File "C:\Users\Hugo Nunes\OneDrive\Área de Trabalho\MVP\desenvolvimento-full-stack-basico\aula-3\meu_app_api\app.py", line 75, in get_clientes
    clientes = session.query(Cliente).all()
               ^^^^^^^^^^^^^^^^^^^^^^
  File "C:\Users\Hugo Nunes\AppData\Local\Programs\Python\Python311\Lib\site-packages\sqlalchemy\orm\session.py", line 2159, in query
    return self._query_cls(entities, self, **kwargs)
           ^^^^^^^^^^^^^^^^^^^^^^^^^^^^^^^^^^^^^^^^^
  File "C:\Users\Hugo Nunes\AppData\Local\Programs\Python\Python311\Lib\site-packages\sqlalchemy\orm\query.py", line 180, in __init__
    self._set_entities(entities)
  File "C:\Users\Hugo Nunes\AppData\Local\Programs\Python\Python311\Lib\site-packages\sqlalchemy\orm\query.py", line 187, in _set_entities
    self._raw_columns = [
                        ^
  File "C:\Users\Hugo Nunes\AppData\Local\Programs\Python\Python311\Lib\site-packages\sqlalchemy\orm\query.py", line 188, in <listcomp>
    coercions.expect(
  File "C:\Users\Hugo Nunes\AppData\Local\Programs\Python\Python311\Lib\site-packages\sqlalchemy\sql\coercions.py", line 181, in expect
    insp._post_inspect
  File "C:\Users\Hugo Nunes\AppData\Local\Programs\Python\Python311\Lib\site-packages\sqlalchemy\util\langhelpers.py", line 1184, in __get__
    obj.__dict__[self.__name__] = result = self.fget(obj)
                                           ^^^^^^^^^^^^^^
  File "C:\Users\Hugo Nunes\AppData\Local\Programs\Python\Python311\Lib\site-packages\sqlalchemy\orm\mapper.py", line 2182, in _post_inspect
    self._check_configure()
  File "C:\Users\Hugo Nunes\AppData\Local\Programs\Python\Python311\Lib\site-packages\sqlalchemy\orm\mapper.py", line 1924, in _check_configure
    _configure_registries({self.registry}, cascade=True)
  File "C:\Users\Hugo Nunes\AppData\Local\Programs\Python\Python311\Lib\site-packages\sqlalchemy\orm\mapper.py", line 3483, in _configure_registries
    _do_configure_registries(registries, cascade)
  File "C:\Users\Hugo Nunes\AppData\Local\Programs\Python\Python311\Lib\site-packages\sqlalchemy\orm\mapper.py", line 3518, in _do_configure_registries
    raise e
sqlalchemy.exc.InvalidRequestError: One or more mappers failed to initialize - can't proceed with initialization of other mappers. Triggering mapper: 'mapped class Cliente->cliente'. Original exception was: When initializing mapper mapped class Cliente->cliente, expression 'Comentario' failed to locate a name ('Comentario'). If this is a class name, consider adding this relationship() to the <class 'model.cliente.Cliente'> class after both dependent classes have been defined.
[2023-11-26 11:02:38,026] INFO _log() L224  127.0.0.1 - - [26/Nov/2023 11:02:38] "[35m[1mGET /clientes HTTP/1.1[0m" 500 - - call_trace=C:\Users\Hugo Nunes\AppData\Local\Programs\Python\Python311\Lib\site-packages\werkzeug\_internal.py L224 
[2023-11-26 11:04:46,333] INFO _log() L224  [31m[1mWARNING: This is a development server. Do not use it in a production deployment. Use a production WSGI server instead.[0m
 * Running on all addresses (0.0.0.0)
 * Running on http://127.0.0.1:5000
 * Running on http://192.168.1.11:5000 - call_trace=C:\Users\Hugo Nunes\AppData\Local\Programs\Python\Python311\Lib\site-packages\werkzeug\_internal.py L224 
[2023-11-26 11:04:46,336] INFO _log() L224  [33mPress CTRL+C to quit[0m - call_trace=C:\Users\Hugo Nunes\AppData\Local\Programs\Python\Python311\Lib\site-packages\werkzeug\_internal.py L224 
[2023-11-26 11:04:52,264] INFO _log() L224  127.0.0.1 - - [26/Nov/2023 11:04:52] "GET /clientes HTTP/1.1" 200 - - call_trace=C:\Users\Hugo Nunes\AppData\Local\Programs\Python\Python311\Lib\site-packages\werkzeug\_internal.py L224 
[2023-11-26 11:04:52,970] INFO _log() L224  127.0.0.1 - - [26/Nov/2023 11:04:52] "GET /clientes HTTP/1.1" 200 - - call_trace=C:\Users\Hugo Nunes\AppData\Local\Programs\Python\Python311\Lib\site-packages\werkzeug\_internal.py L224 
[2023-11-26 11:04:53,322] INFO _log() L224  127.0.0.1 - - [26/Nov/2023 11:04:53] "GET /clientes HTTP/1.1" 200 - - call_trace=C:\Users\Hugo Nunes\AppData\Local\Programs\Python\Python311\Lib\site-packages\werkzeug\_internal.py L224 
[2023-11-26 11:05:32,043] INFO _log() L224  127.0.0.1 - - [26/Nov/2023 11:05:32] "[33mPOST /produto HTTP/1.1[0m" 404 - - call_trace=C:\Users\Hugo Nunes\AppData\Local\Programs\Python\Python311\Lib\site-packages\werkzeug\_internal.py L224 
[2023-11-26 11:05:43,609] INFO _log() L224  127.0.0.1 - - [26/Nov/2023 11:05:43] "GET /clientes HTTP/1.1" 200 - - call_trace=C:\Users\Hugo Nunes\AppData\Local\Programs\Python\Python311\Lib\site-packages\werkzeug\_internal.py L224 
[2023-11-26 11:05:50,307] INFO _log() L224  127.0.0.1 - - [26/Nov/2023 11:05:50] "GET /clientes HTTP/1.1" 200 - - call_trace=C:\Users\Hugo Nunes\AppData\Local\Programs\Python\Python311\Lib\site-packages\werkzeug\_internal.py L224 
[2023-11-26 11:05:56,648] INFO _log() L224  127.0.0.1 - - [26/Nov/2023 11:05:56] "GET /clientes HTTP/1.1" 200 - - call_trace=C:\Users\Hugo Nunes\AppData\Local\Programs\Python\Python311\Lib\site-packages\werkzeug\_internal.py L224 
[2023-11-26 11:06:03,864] INFO _log() L224  127.0.0.1 - - [26/Nov/2023 11:06:03] "GET /clientes HTTP/1.1" 200 - - call_trace=C:\Users\Hugo Nunes\AppData\Local\Programs\Python\Python311\Lib\site-packages\werkzeug\_internal.py L224 
[2023-11-26 11:08:27,410] INFO _log() L224  127.0.0.1 - - [26/Nov/2023 11:08:27] "GET /clientes HTTP/1.1" 200 - - call_trace=C:\Users\Hugo Nunes\AppData\Local\Programs\Python\Python311\Lib\site-packages\werkzeug\_internal.py L224 
[2023-11-26 11:08:32,414] INFO _log() L224  127.0.0.1 - - [26/Nov/2023 11:08:32] "GET /clientes HTTP/1.1" 200 - - call_trace=C:\Users\Hugo Nunes\AppData\Local\Programs\Python\Python311\Lib\site-packages\werkzeug\_internal.py L224 
[2023-11-26 11:18:38,047] INFO _log() L224  127.0.0.1 - - [26/Nov/2023 11:18:38] "[32mGET / HTTP/1.1[0m" 302 - - call_trace=C:\Users\Hugo Nunes\AppData\Local\Programs\Python\Python311\Lib\site-packages\werkzeug\_internal.py L224 
[2023-11-26 11:18:38,520] INFO _log() L224  127.0.0.1 - - [26/Nov/2023 11:18:38] "GET /openapi/ HTTP/1.1" 200 - - call_trace=C:\Users\Hugo Nunes\AppData\Local\Programs\Python\Python311\Lib\site-packages\werkzeug\_internal.py L224 
[2023-11-26 11:18:38,824] INFO _log() L224  127.0.0.1 - - [26/Nov/2023 11:18:38] "[36mGET /openapi/static/images/swagger.svg HTTP/1.1[0m" 304 - - call_trace=C:\Users\Hugo Nunes\AppData\Local\Programs\Python\Python311\Lib\site-packages\werkzeug\_internal.py L224 
[2023-11-26 11:18:38,928] INFO _log() L224  127.0.0.1 - - [26/Nov/2023 11:18:38] "[36mGET /openapi/static/images/redoc.svg HTTP/1.1[0m" 304 - - call_trace=C:\Users\Hugo Nunes\AppData\Local\Programs\Python\Python311\Lib\site-packages\werkzeug\_internal.py L224 
[2023-11-26 11:18:39,012] INFO _log() L224  127.0.0.1 - - [26/Nov/2023 11:18:39] "[36mGET /openapi/static/images/rapidoc.svg HTTP/1.1[0m" 304 - - call_trace=C:\Users\Hugo Nunes\AppData\Local\Programs\Python\Python311\Lib\site-packages\werkzeug\_internal.py L224 
[2023-11-26 11:18:39,358] INFO _log() L224  127.0.0.1 - - [26/Nov/2023 11:18:39] "[36mGET /openapi/static/images/apidoc.svg HTTP/1.1[0m" 304 - - call_trace=C:\Users\Hugo Nunes\AppData\Local\Programs\Python\Python311\Lib\site-packages\werkzeug\_internal.py L224 
[2023-11-26 11:18:49,143] INFO _log() L224  127.0.0.1 - - [26/Nov/2023 11:18:49] "GET /openapi/swagger HTTP/1.1" 200 - - call_trace=C:\Users\Hugo Nunes\AppData\Local\Programs\Python\Python311\Lib\site-packages\werkzeug\_internal.py L224 
[2023-11-26 11:18:49,338] INFO _log() L224  127.0.0.1 - - [26/Nov/2023 11:18:49] "[36mGET /openapi/static/css/swagger-ui.css HTTP/1.1[0m" 304 - - call_trace=C:\Users\Hugo Nunes\AppData\Local\Programs\Python\Python311\Lib\site-packages\werkzeug\_internal.py L224 
[2023-11-26 11:18:49,633] INFO _log() L224  127.0.0.1 - - [26/Nov/2023 11:18:49] "[36mGET /openapi/static/js/swagger-ui-bundle.js HTTP/1.1[0m" 304 - - call_trace=C:\Users\Hugo Nunes\AppData\Local\Programs\Python\Python311\Lib\site-packages\werkzeug\_internal.py L224 
